Workbook

Sheet Lineas
A1: n° Linea | B1: modulo | C1: boyas | D1: Grilletes | E1: Cabos | F1: Pulgueras | G1: Cables | H1: cadenas | I1: pernos anclaje | J1: peso muerto | K1: anclas | L1: guardacabos | M1: anillos de distribución
A2: C01 | B2: 100 | C2: 2 | D2: 26 | E2: =80+180 -> 260 | F2: 1 | G2: 0 | H2: =5+10+1+27.5+385+13.75*2 -> 456 | I2: 2 | J2: 0 | K2: 0 | L2: 0 | M2: 4
A3: C02 | B3: 100 | C3: 0 | D3: 28 | E3: =80+150 -> 230 | F3: 1 | G3: 0 | H3: =5+10+1+27.5*2+412.5+13.75*2 -> 511 | I3: 2 | J3: 0 | K3: 0 | L3: 0 | M3: 4
A4: C03 | B4: 100 | C4: 0 | D4: 26 | E4: =80+180 -> 260 | F4: 1 | G4: 0 | H4: =5+10+1+27.5+440+13.75*2 -> 511 | I4: 2 | J4: 0 | K4: 0 | L4: 0 | M4: 4
A5: C04 | B5: 100 | C5: 2 | D5: 26 | E5: =75+180 -> 255 | F5: 1 | G5: 0 | H5: =5+10+1+27.5+481.25+13.75*2 -> 552.25 | I5: 2 | J5: 0 | K5: 0 | L5: 0 | M5: 4
A6: C05 | B6: 100 | C6: 0 | D6: 26 | E6: =75+150 -> 225 | F6: 1 | G6: 0 | H6: =5+10+1+27.5+481.25+13.75*2 -> 552.25 | I6: 2 | J6: 0 | K6: 0 | L6: 0 | M6: 4
A7: C06 | B7: 100 | C7: 0 | D7: 26 | E7: =75+180 -> 255 | F7: 1 | G7: 0 | H7: =5+10+1+27.5+481.25+13.75*2 -> 552.25 | I7: 2 | J7: 0 | K7: 0 | L7: 0 | M7: 4
A8: C07 | B8: 100 | C8: 0 | D8: 26 | E8: =80+180 -> 260 | F8: 1 | G8: 0 | H8: =5+10+1+27.5+481.25+13.75*2 -> 552.25 | I8: 2 | J8: 0 | K8: 0 | L8: 0 | M8: 4
A9: C08 | B9: 100 | C9: 2 | D9: 26 | E9: =80+330 -> 410 | F9: 1 | G9: 0 | H9: =5+10+1+27.5+481.25+13.75*2 -> 552.25 | I9: 2 | J9: 0 | K9: 0 | L9: 0 | M9: 4
A10: C09 | B10: 100 | C10: 0 | D10: 26 | E10: =80+300 -> 380 | F10: 1 | G10: 0 | H10: =5+10+1+27.5+481.25+13.75*2 -> 552.25 | I10: 2 | J10: 0 | K10: 0 | L10: 0 | M10: 4
A11: C10 | B11: 100 | C11: 0 | D11: 26 | E11: =80+330 -> 410 | F11: 1 | G11: 0 | H11: =5+10+1+27.5+481.25+13.75*2 -> 552.25 | I11: 2 | J11: 0 | K11: 0 | L11: 0 | M11: 4
A12: L11 | B12: 100 | C12: 2 | D12: 18 | E12: 440 | F12: 0 | G12: 30 | H12: =165 -> 165 | I12: 0 | J12: 0 | K12: 1 | L12: 0 | M12: 2
A13: L12 | B13: 100 | C13: 0 | D13: 18 | E13: 430 | F13: 0 | G13: 30 | H13: 110 | I13: 0 | J13: 0 | K13: 1 | L13: 0 | M13: 2
A14: L13 | B14: 100 | C14: 0 | D14: 18 | E14: 440 | F14: 0 | G14: 30 | H14: 137.5 | I14: 0 | J14: 0 | K14: 1 | L14: 0 | M14: 2
A15: L14 | B15: 100 | C15: 2 | D15: 18 | E15: 420 | F15: 0 | G15: 30 | H15: =165 -> 165 | I15: 0 | J15: 0 | K15: 1 | L15: 0 | M15: 2
A16: L15 | B16: 100 | C16: 0 | D16: 18 | E16: 435 | F16: 0 | G16: 30 | H16: 110 | I16: 0 | J16: 0 | K16: 1 | L16: 0 | M16: 2
A17: L16 | B17: 100 | C17: 0 | D17: 18 | E17: 440 | F17: 0 | G17: 30 | H17: 137.5 | I17: 0 | J17: 0 | K17: 1 | L17: 0 | M17: 2
A18: L17 | B18: 100 | C18: 2 | D18: 18 | E18: 440 | F18: 0 | G18: 30 | H18: =165 -> 165 | I18: 0 | J18: 0 | K18: 1 | L18: 0 | M18: 2
A19: L18 | B19: 100 | C19: 0 | D19: 18 | E19: 430 | F19: 0 | G19: 30 | H19: 110 | I19: 0 | J19: 0 | K19: 1 | L19: 0 | M19: 2
A20: L19 | B20: 100 | C20: 0 | D20: 18 | E20: 435 | F20: 0 | G20: 30 | H20: 137.5 | I20: 0 | J20: 0 | K20: 1 | L20: 0 | M20: 2
A21: L20 | B21: 100 | C21: 2 | D21: 18 | E21: 440 | F21: 0 | G21: 30 | H21: =165 -> 165 | I21: 0 | J21: 0 | K21: 1 | L21: 0 | M21: 2
A22: L21 | B22: 100 | C22: 0 | D22: 18 | E22: 430 | F22: 0 | G22: 30 | H22: 110 | I22: 0 | J22: 0 | K22: 1 | L22: 0 | M22: 2
A23: L22 | B23: 100 | C23: 0 | D23: 18 | E23: 435 | F23: 0 | G23: 30 | H23: 137.5 | I23: 0 | J23: 0 | K23: 1 | L23: 0 | M23: 2
A24: L23 | B24: 100 | C24: 2 | D24: 18 | E24: 440 | F24: 0 | G24: 30 | H24: =165 -> 165 | I24: 0 | J24: 0 | K24: 1 | L24: 0 | M24: 2
A25: L24 | B25: 100 | C25: 0 | D25: 18 | E25: 430 | F25: 0 | G25: 30 | H25: 110 | I25: 0 | J25: 0 | K25: 1 | L25: 0 | M25: 2
A26: L25 | B26: 100 | C26: 0 | D26: 18 | E26: 435 | F26: 0 | G26: 30 | H26: 137.5 | I26: 0 | J26: 0 | K26: 1 | L26: 0 | M26: 2
A27: L26 | B27: 100 | C27: 2 | D27: 18 | E27: 445 | F27: 0 | G27: 30 | H27: =165 -> 165 | I27: 0 | J27: 0 | K27: 1 | L27: 0 | M27: 2
A28: L27 | B28: 100 | C28: 0 | D28: 18 | E28: 435 | F28: 0 | G28: 30 | H28: 110 | I28: 0 | J28: 0 | K28: 1 | L28: 0 | M28: 2
A29: L28 | B29: 100 | C29: 0 | D29: 18 | E29: 440 | F29: 0 | G29: 30 | H29: 137.5 | I29: 0 | J29: 0 | K29: 1 | L29: 0 | M29: 2
A30: C29 | B30: 100 | C30: 3 | D30: 22 | E30: 1020 | F30: 0 | G30: 0 | H30: 82.5 | I30: 0 | J30: 0 | K30: 1 | L30: 0 | M30: 2
A31: C30 | B31: 100 | C31: 0 | D31: 22 | E31: 1130 | F31: 0 | G31: 0 | H31: 82.5 | I31: 0 | J31: 0 | K31: 1 | L31: 0 | M31: 2
A32: C31 | B32: 100 | C32: 0 | D32: 22 | E32: 910 | F32: 0 | G32: 0 | H32: 82.5 | I32: 0 | J32: 0 | K32: 1 | L32: 0 | M32: 2
A33: C32 | B33: 100 | C33: 0 | D33: 22 | E33: 1020 | F33: 0 | G33: 0 | H33: 82.5 | I33: 0 | J33: 0 | K33: 1 | L33: 0 | M33: 2
A34: C33 | B34: 100 | C34: 3 | D34: 22 | E34: 1020 | F34: 0 | G34: 0 | H34: 82.5 | I34: 0 | J34: 0 | K34: 1 | L34: 0 | M34: 2
A35: C34 | B35: 100 | C35: 0 | D35: 22 | E35: 910 | F35: 0 | G35: 0 | H35: 82.5 | I35: 0 | J35: 0 | K35: 1 | L35: 0 | M35: 2
A36: C35 | B36: 100 | C36: 0 | D36: 22 | E36: 1020 | F36: 0 | G36: 0 | H36: 82.5 | I36: 0 | J36: 0 | K36: 1 | L36: 0 | M36: 2
A37: C36 | B37: 100 | C37: 0 | D37: 22 | E37: 910 | F37: 0 | G37: 0 | H37: 82.5 | I37: 0 | J37: 0 | K37: 1 | L37: 0 | M37: 2
A38: C37 | B38: 100 | C38: 0 | D38: 22 | E38: 1020 | F38: 0 | G38: 0 | H38: 82.5 | I38: 0 | J38: 0 | K38: 1 | L38: 0 | M38: 2
A39: C38 | B39: 100 | C39: 3 | D39: 22 | E39: 1020 | F39: 0 | G39: 0 | H39: 82.5 | I39: 0 | J39: 0 | K39: 1 | L39: 0 | M39: 2
... A43: L42 | B43: 100 | C43: 2 | D43: 22 | E43: 1020 | F43: 1 | G43: 0 | H43: 82.5 | I43: 2 | J43: 1 | K43: 1 | L43: 0 | M43: 2
...

Sheet Notas
A1: Alcance | B1: Total Mod 100 | C1: Total Mod 200
A2: Boyas | B2: =SUMIF(Lineas!$B$2:$B$36,100,Lineas!$C$2:$C$36) -> 24 | C2: =SUMIF(Lineas!$B$2:$B$36,200,Lineas!$C$2:$C$36) -> 0 | D2: Unidad
A3: Grilletes | B3: =SUMIF(Lineas!$B$2:$B$36,100,Lineas!$D$2:$D$36) -> 740 | C3: =SUMIF(Lineas!$B$2:$B$36,200,Lineas!$D$2:$D$36) -> 0 | D3: Unidad
A4: Cabos | B4: =SUMIF(Lineas!$B$2:$B$36,100,Lineas!$E$2:$E$36)/220 -> 80.977273 | C4: =SUMIF(Lineas!$B$2:$B$36,200,Lineas!$E$2:$E$36)/220 -> 0 | D4: paños
A5: Cables | B5: =SUMIF(Lineas!$B$2:$B$36,100,Lineas!$G$2:$G$36)/220 -> 2.4545455 | C5: =SUMIF(Lineas!$B$2:$B$36,200,Lineas!$G$2:$G$36)/220 -> 0 | D5: paños
A6: Cadenas | B6: =SUMIF(Lineas!$B$2:$B$36,100,Lineas!$H$2:$H$36)/27.5 -> 305.31818 | C6: =SUMIF(Lineas!$B$2:$B$36,200,Lineas!$H$2:$H$36)/27.5 -> 0 | D6: paños
A7: Pernos Anclaje | B7: =SUMIF(Lineas!$B$2:$B$36,100,Lineas!$I$2:$I$36) -> 20 | C7: =SUMIF(Lineas!$B$2:$B$36,200,Lineas!$I$2:$I$36) -> 0 | D7: Unidad
A8: Pesos Muerto | B8: =SUMIF(Lineas!$B$2:$B$36,100,Lineas!$J$2:$J$36) -> 0 | C8: =SUMIF(Lineas!$B$2:$B$36,200,Lineas!$J$2:$J$36) -> 0 | D8: Unidad
A9: Anclas | B9: =SUMIF(Lineas!$B$2:$B$36,100,Lineas!$K$2:$K$36) -> 25 | C9: =SUMIF(Lineas!$B$2:$B$36,200,Lineas!$K$2:$K$36) -> 0 | D9: Unidad
A10: Guardacabos | B10: =SUMIF(Lineas!$B$2:$B$36,100,Lineas!$L$2:$L$36) -> 0 | C10: =SUMIF(Lineas!$B$2:$B$36,200,Lineas!$L$2:$L$36) -> 0 | D10: Unidad
A11: Anillos de distribución | B11: =SUMIF(Lineas!$B$2:$B$36,100,Lineas!$M$2:$M$36) -> 90 | C11: =SUMIF(Lineas!$B$2:$B$36,200,Lineas!$M$2:$M$36) -> 0 | D11: Unidad
A14: Linea mod 100 | B14: =COUNTIF(Lineas!$B$2:$B$36,100) -> 35
A15: Linea mod 100 | B15: =COUNTIF(Lineas!$B$2:$B$36,200) -> 0
A18: Largo Lineas
E20: =SUM(B20:D20) -> 716
E21: =SUM(B21:D21) -> 741
E22: =SUM(B22:D22) -> 771
E23: =SUM(B23:D23) -> 807.25
E24: =SUM(B24:D24) -> 777.25
E25: =SUM(B25:D25) -> 807.25
E26: =SUM(B26:D26) -> 812.25
E27: =SUM(B27:D27) -> 962.25
E28: =SUM(B28:D28) -> 932.25
E29: =SUM(B29:D29) -> 962.25
E30: =SUM(B30:D30) -> 1102.5
E31: =SUM(B31:D31) -> 1212.5
... E78: =SUM(B78:D78) -> 288.75
